Workbook

Sheet Characters
A1: ID | B1: Name | C1: Category | D1: Description | E1: Gender | F1: Nationality | G1: Birth Year | H1: Popularity (1-100) | I1: Active | J1: Retired | K1: Profession | L1: Sport | M1: Team | N1: League | O1: Position | P1: Athlete | Q1: Captain | R1: Batsman | S1: Bowler | T1: All-Rounder | U1: Wicketkeeper | V1: World Cup Winner | W1: Champions League Winner | X1: Olympic Medalist | Y1: Major Champion | Z1: Actor | AA1: Actress | AB1: Singer | AC1: Director | AD1: Known for Comedy | AE1: Marvel | AF1: Oscar Winner | AG1: Grammy Winner | AH1: Solo Artist | AI1: Band Member | AJ1: Entrepreneur | AK1: Founder | AL1: Billionaire | AM1: Streamer/YouTuber | AN1: Indian | AO1: American | AP1: British | AQ1: European | AR1: Fictional | AS1: Fictional Origin | AT1: Hero/Villain
A2: fb-hegerberg | B2: Ada Hegerberg | C2: Footballers | D2: Norwegian forward, women's football | E2: female | F2: Norway | G2: 1995 | H2: 60 | I2: =TRUE() | J2: =FALSE() | K2: Footballer | L2: Football | M2: Olympique Lyonnais | N2: Division 1 Féminine | O2: Forward | P2: =TRUE() | Q2: =FALSE() | V2: =FALSE() | W2: =TRUE() | AQ2: =TRUE()
A3: fb-alexmorgan | B3: Alex Morgan | C3: Footballers | D3: American forward, women's football, retired | E3: female | F3: USA | G3: 1989 | H3: 60 | I3: =FALSE() | J3: =TRUE() | K3: Footballer | L3: Football | M3: San Diego Wave | N3: NWSL | O3: Forward | P3: =TRUE() | Q3: =FALSE() | V3: =TRUE() | AO3: =TRUE() | AQ3: =FALSE()
A4: fb-alisson | B4: Alisson Becker | C4: Footballers | D4: Brazilian goalkeeper, Liverpool FC | E4: male | F4: Brazil | G4: 1992 | H4: 60 | I4: =TRUE() | J4: =FALSE() | K4: Footballer | L4: Football | M4: Liverpool FC | N4: Premier League | O4: Goalkeeper | P4: =TRUE() | Q4: =FALSE() | V4: =FALSE() | W4: =TRUE() | AQ4: =FALSE()
A5: fb-pirlo | B5: Andrea Pirlo | C5: Footballers | D5: Italian midfielder, retired | E5: male | F5: Italy | G5: 1979 | H5: 60 | I5: =FALSE() | J5: =TRUE() | K5: Footballer | L5: Football | M5: Juventus | N5: Serie A | O5: Midfielder | P5: =TRUE() | Q5: =FALSE() | V5: =TRUE() | W5: =TRUE() | AQ5: =TRUE()
A6: fb-iniesta | B6: Andrés Iniesta | C6: Footballers | D6: Spanish midfielder, retired from Europe | E6: male | F6: Spain | G6: 1984 | H6: 60 | I6: =TRUE() | J6: =FALSE() | K6: Footballer | L6: Football | M6: Emirates Club | N6: UAE Pro League | O6: Midfielder | P6: =TRUE() | Q6: =FALSE() | V6: =TRUE() | W6: =TRUE() | AQ6: =TRUE()
A7: fb-griezmann | B7: Antoine Griezmann | C7: Footballers | D7: French forward, Atlético Madrid | E7: male | F7: France | G7: 1991 | H7: 60 | I7: =TRUE() | J7: =FALSE() | K7: Footballer | L7: Football | M7: Atlético Madrid | N7: La Liga | O7: Forward | P7: =TRUE() | Q7: =FALSE() | V7: =TRUE() | W7: =FALSE() | AQ7: =TRUE()
A8: fb-saka | B8: Bukayo Saka | C8: Footballers | D8: English forward, Arsenal FC | E8: male | F8: England | G8: 2001 | H8: 60 | I8: =TRUE() | J8: =FALSE() | K8: Footballer | L8: Football | M8: Arsenal FC | N8: Premier League | O8: Forward | P8: =TRUE() | Q8: =FALSE() | V8: =FALSE() | W8: =FALSE() | AP8: =TRUE() | AQ8: =TRUE()
A9: fb-ronaldo-cr7 | B9: Cristiano Ronaldo | C9: Footballers | D9: Portuguese forward, Al Nassr FC | E9: male | F9: Portugal | G9: 1985 | H9: 99 | I9: =TRUE() | J9: =FALSE() | K9: Footballer | L9: Football | M9: Al Nassr FC | N9: Saudi Pro League | O9: Forward | P9: =TRUE() | Q9: =TRUE() | V9: =FALSE() | W9: =TRUE() | AQ9: =TRUE()
A10: fb-beckham | B10: David Beckham | C10: Footballers | D10: English former midfielder, now club owner | E10: male | F10: England | G10: 1975 | H10: 87 | I10: =FALSE() | J10: =TRUE() | K10: Footballer; Entrepreneur | L10: Football | M10: Manchester United | N10: Premier League | O10: Midfielder | P10: =TRUE() | Q10: =TRUE() | V10: =FALSE() | W10: =TRUE() | AJ10: =TRUE() | AP10: =TRUE() | AQ10: =TRUE()
A11: fb-drogba | B11: Didier Drogba | C11: Footballers | D11: Ivorian former forward | E11: male | F11: Ivory Coast | G11: 1978 | H11: 60 | I11: =FALSE() | J11: =TRUE() | K11: Footballer | L11: Football | M11: Chelsea FC | N11: Premier League | O11: Forward | P11: =TRUE() | Q11: =TRUE() | V11: =FALSE() | W11: =TRUE() | AQ11: =FALSE()
A12: fb-maradona | B12: Diego Maradona | C12: Footballers | D12: Argentine football legend | E12: male | F12: Argentina | G12: 1960 | H12: 95 | I12: =FALSE() | J12: =TRUE() | K12: Footballer | L12: Football | M12: Napoli | N12: Serie A | O12: Forward | P12: =TRUE() | Q12: =TRUE() | V12: =TRUE() | W12: =FALSE() | AQ12: =FALSE()
A13: fb-ederson | B13: Ederson | C13: Footballers | D13: Brazilian goalkeeper, Manchester City | E13: male | F13: Brazil | G13: 1993 | H13: 60 | I13: =TRUE() | J13: =FALSE() | K13: Footballer | L13: Football | M13: Manchester City | N13: Premier League | O13: Goalkeeper | P13: =TRUE() | Q13: =FALSE() | V13: =FALSE() | W13: =TRUE() | AQ13: =FALSE()
A14: fb-cavani | B14: Edinson Cavani | C14: Footballers | D14: Uruguayan forward | E14: male | F14: Uruguay | G14: 1987 | H14: 60 | I14: =TRUE() | J14: =FALSE() | K14: Footballer | L14: Football | M14: Boca Juniors | N14: Argentine Primera División | O14: Forward | P14: =TRUE() | Q14: =FALSE() | V14: =FALSE() | W14: =FALSE() | AQ14: =FALSE()
A15: fb-haaland | B15: Erling Haaland | C15: Footballers | D15: Norwegian forward, Manchester City | E15: male | F15: Norway | G15: 2000 | H15: 88 | I15: =TRUE() | J15: =FALSE() | K15: Footballer | L15: Football | M15: Manchester City | N15: Premier League | O15: Forward | P15: =TRUE() | Q15: =FALSE() | V15: =FALSE() | W15: =TRUE() | AQ15: =TRUE()
A16: fb-eusebio | B16: Eusébio | C16: Footballers | D16: Portuguese football legend | E16: male | F16: Portugal | G16: 1942 | H16: 60 | I16: =FALSE() | J16: =TRUE() | K16: Footballer | L16: Football | M16: Benfica | N16: Primeira Liga | O16: Forward | P16: =TRUE() | Q16: =FALSE() | V16: =FALSE() | W16: =TRUE() | AQ16: =TRUE()
A17: fb-beckenbauer | B17: Franz Beckenbauer | C17: Footballers | D17: German football legend, defender | E17: male | F17: Germany | G17: 1945 | H17: 60 | I17: =FALSE() | J17: =TRUE() | K17: Footballer | L17: Football | M17: Bayern Munich | N17: Bundesliga | O17: Defender | P17: =TRUE() | Q17: =TRUE() | V17: =TRUE() | W17: =TRUE() | AQ17: =TRUE()
A18: fb-defrenkie | B18: Frenkie de Jong | C18: Footballers | D18: Dutch midfielder, FC Barcelona | E18: male | F18: Netherlands | G18: 1997 | H18: 60 | I18: =TRUE() | J18: =FALSE() | K18: Footballer | L18: Football | M18: FC Barcelona | N18: La Liga | O18: Midfielder | P18: =TRUE() | Q18: =FALSE() | V18: =FALSE() | W18: =FALSE() | AQ18: =TRUE()
A19: fb-georgebest | B19: George Best | C19: Footballers | D19: Northern Irish forward, football legend | E19: male | F19: Northern Ireland | G19: 1946 | H19: 60 | I19: =FALSE() | J19: =TRUE() | K19: Footballer | L19: Football | M19: Manchester United | N19: Premier League | O19: Forward | P19: =TRUE() | Q19: =FALSE() | V19: =FALSE() | W19: =TRUE() | AQ19: =TRUE()
A20: fb-buffon | B20: Gianluigi Buffon | C20: Footballers | D20: Italian goalkeeper, retired | E20: male | F20: Italy | G20: 1978 | H20: 60 | I20: =FALSE() | J20: =TRUE() | K20: Footballer | L20: Football | M20: Juventus | N20: Serie A | O20: Goalkeeper | P20: =TRUE() | Q20: =TRUE() | V20: =TRUE() | W20: =FALSE() | AQ20: =TRUE()
A21: fb-kane | B21: Harry Kane | C21: Footballers | D21: English forward, Bayern Munich | E21: male | F21: England | G21: 1993 | H21: 60 | I21: =TRUE() | J21: =FALSE() | K21: Footballer | L21: Football | M21: Bayern Munich | N21: Bundesliga | O21: Forward | P21: =TRUE() | Q21: =TRUE() | V21: =FALSE() | W21: =FALSE() | AP21: =TRUE() | AQ21: =TRUE()
A22: fb-casillas | B22: Iker Casillas | C22: Footballers | D22: Spanish goalkeeper, retired | E22: male | F22: Spain | G22: 1981 | H22: 60 | I22: =FALSE() | J22: =TRUE() | K22: Footballer | L22: Football | M22: Real Madrid | N22: La Liga | O22: Goalkeeper | P22: =TRUE() | Q22: =TRUE() | V22: =TRUE() | W22: =TRUE() | AQ22: =TRUE()
A23: fb-cruyff | B23: Johan Cruyff | C23: Footballers | D23: Dutch football legend | E23: male | F23: Netherlands | G23: 1947 | H23: 60 | I23: =FALSE() | J23: =TRUE() | K23: Footballer | L23: Football | M23: Ajax | N23: Eredivisie | O23: Forward | P23: =TRUE() | Q23: =TRUE() | V23: =FALSE() | W23: =TRUE() | AQ23: =TRUE()
A24: fb-bellingham | B24: Jude Bellingham | C24: Footballers | D24: English midfielder, Real Madrid | E24: male | F24: England | G24: 2003 | H24: 60 | I24: =TRUE() | J24: =FALSE() | K24: Footballer | L24: Football | M24: Real Madrid | N24: La Liga | O24: Midfielder | P24: =TRUE() | Q24: =FALSE() | V24: =FALSE() | W24: =TRUE() | AP24: =TRUE() | AQ24: =TRUE()
A25: fb-benzema | B25: Karim Benzema | C25: Footballers | D25: French forward, Al-Ittihad | E25: male | F25: France | G25: 1987 | H25: 60 | I25: =TRUE() | J25: =FALSE() | K25: Footballer | L25: Football | M25: Al-Ittihad | N25: Saudi Pro League | O25: Forward | P25: =TRUE() | Q25: =FALSE() | V25: =TRUE() | W25: =TRUE() | AQ25: =TRUE()
A26: fb-debruyne | B26: Kevin De Bruyne | C26: Footballers | D26: Belgian midfielder | E26: male | F26: Belgium | G26: 1991 | H26: 60 | I26: =TRUE() | J26: =FALSE() | K26: Footballer | L26: Football | M26: Napoli | N26: Serie A | O26: Midfielder | P26: =TRUE() | Q26: =TRUE() | V26: =FALSE() | W26: =TRUE() | AQ26: =TRUE()
A27: fb-mbappe | B27: Kylian Mbappé | C27: Footballers | D27: French forward, Real Madrid | E27: male | F27: France | G27: 1998 | H27: 92 | I27: =TRUE() | J27: =FALSE() | K27: Footballer | L27: Football | M27: Real Madrid | N27: La Liga | O27: Forward | P27: =TRUE() | Q27: =TRUE() | V27: =TRUE() | W27: =FALSE() | AQ27: =TRUE()
A28: fb-messi | B28: Lionel Messi | C28: Footballers | D28: Argentine forward, Inter Miami CF | E28: male | F28: Argentina | G28: 1987 | H28: 99 | I28: =TRUE() | J28: =FALSE() | K28: Footballer | L28: Football | M28: Inter Miami CF | N28: MLS | O28: Forward | P28: =TRUE() | Q28: =TRUE() | V28: =TRUE() | W28: =TRUE() | AQ28: =FALSE()
A29: fb-suarez | B29: Luis Suárez | C29: Footballers | D29: Uruguayan forward | E29: male | F29: Uruguay | G29: 1987 | H29: 60 | I29: =TRUE() | J29: =FALSE() | K29: Footballer | L29: Football | M29: Inter Miami CF | N29: MLS | O29: Forward | P29: =TRUE() | Q29: =FALSE() | V29: =FALSE() | W29: =TRUE() | AQ29: =FALSE()
A30: fb-modric | B30: Luka Modrić | C30: Footballers | D30: Croatian midfielder, Real Madrid | E30: male | F30: Croatia | G30: 1985 | H30: 60 | I30: =TRUE() | J30: =FALSE() | K30: Footballer | L30: Football | M30: Real Madrid | N30: La Liga | O30: Midfielder | P30: =TRUE() | Q30: =TRUE() | V30: =FALSE() | W30: =TRUE() | AQ30: =TRUE()
A31: fb-neuer | B31: Manuel Neuer | C31: Footballers | D31: German goalkeeper, Bayern Munich | E31: male | F31: Germany | G31: 1986 | H31: 60 | I31: =TRUE() | J31: =FALSE() | K31: Footballer | L31: Football | M31: Bayern Munich | N31: Bundesliga | O31: Goalkeeper | P31: =TRUE() | Q31: =TRUE() | V31: =TRUE() | W31: =TRUE() | AQ31: =TRUE()
A32: fb-marta | B32: Marta | C32: Footballers | D32: Brazilian forward, women's football icon | E32: female | F32: Brazil | G32: 1986 | H32: 60 | I32: =TRUE() | J32: =FALSE() | K32: Footballer | L32: Football | M32: Orlando Pride | N32: NWSL | O32: Forward | P32: =TRUE() | Q32: =TRUE() | V32: =FALSE() | AQ32: =FALSE()
A33: fb-rapinoe | B33: Megan Rapinoe | C33: Footballers | D33: American forward, women's football, retired | E33: female | F33: USA | G33: 1985 | H33: 60 | I33: =FALSE() | J33: =TRUE() | K33: Footballer | L33: Football | M33: OL Reign | N33: NWSL | O33: Forward | P33: =TRUE() | Q33: =TRUE() | V33: =TRUE() | AO33: =TRUE() | AQ33: =FALSE()
A34: fb-salah | B34: Mohamed Salah | C34: Footballers | D34: Egyptian forward, Liverpool FC | E34: male | F34: Egypt | G34: 1992 | H34: 60 | I34: =TRUE() | J34: =FALSE() | K34: Footballer | L34: Football | M34: Liverpool FC | N34: Premier League | O34: Forward | P34: =TRUE() | Q34: =TRUE() | V34: =FALSE() | W34: =TRUE() | AQ34: =FALSE()
A35: fb-kante | B35: N'Golo Kanté | C35: Footballers | D35: French midfielder, Al-Ittihad | E35: male | F35: France | G35: 1991 | H35: 60 | I35: =TRUE() | J35: =FALSE() | K35: Footballer | L35: Football | M35: Al-Ittihad | N35: Saudi Pro League | O35: Midfielder | P35: =TRUE() | Q35: =FALSE() | V35: =TRUE() | W35: =TRUE() | AQ35: =TRUE()
A36: fb-neymar | B36: Neymar Jr. | C36: Footballers | D36: Brazilian forward, Santos FC | E36: male | F36: Brazil | G36: 1992 | H36: 90 | I36: =TRUE() | J36: =FALSE() | K36: Footballer | L36: Football | M36: Santos FC | N36: Brasileirão | O36: Forward | P36: =TRUE() | Q36: =FALSE() | V36: =FALSE() | W36: =TRUE() | AQ36: =FALSE()
A37: fb-maldini | B37: Paolo Maldini | C37: Footballers | D37: Italian defender, retired | E37: male | F37: Italy | G37: 1968 | H37: 60 | I37: =FALSE() | J37: =TRUE() | K37: Footballer | L37: Football | M37: AC Milan | N37: Serie A | O37: Defender | P37: =TRUE() | Q37: =TRUE() | V37: =FALSE() | W37: =TRUE() | AQ37: =TRUE()
A38: fb-pele | B38: Pelé | C38: Footballers | D38: Brazilian football legend | E38: male | F38: Brazil | G38: 1940 | H38: 96 | I38: =FALSE() | J38: =TRUE() | K38: Footballer | L38: Football | M38: Santos FC | N38: Brasileirão | O38: Forward | P38: =TRUE() | Q38: =TRUE() | V38: =TRUE() | W38: =FALSE() | AQ38: =FALSE()
A39: fb-mahrez | B39: Riyad Mahrez | C39: Footballers | D39: Algerian forward | E39: male | F39: Algeria | G39: 1991 | H39: 60 | I39: =TRUE() | J39: =FALSE() | K39: Footballer | L39: Football | M39: Al-Ahli | N39: Saudi Pro League | O39: Forward | P39: =TRUE() | Q39: =TRUE() | V39: =FALSE() | W39: =TRUE() | AQ39: =FALSE()
A40: fb-lewandowski | B40: Robert Lewandowski | C40: Footballers | D40: Polish forward, FC Barcelona | E40: male | F40: Poland | G40: 1988 | H40: 60 | I40: =TRUE() | J40: =FALSE() | K40: Footballer | L40: Football | M40: FC Barcelona | N40: La Liga | O40: Forward | P40: =TRUE() | Q40: =TRUE() | V40: =FALSE() | W40: =TRUE() | AQ40: =TRUE()
...

Sheet Attribute Reference
A1: Attribute Reference — how characters are divided/classified
A2: Every yes/no question in the game is generated from one of these attributes. A blank cell for a character just means that attribute doesn't apply to their category (e.g. cricketers have no "marvel" field) — it's never a missing fact.
A4: Attribute | B4: What it means | C4: Used by categories
A5: IDENTITY
A6: gender | B6: male / female | C6: All categories with real people
A7: nationality | B7: Country/countries of origin (semicolon-separated if more than one) | C7: All real-person categories
A8: indian / american / british / european | B8: Quick regional flags used for broad identity questions | C8: All real-person categories
A9: birthYear | B9: Year of birth | C9: All real-person categories (where confidently known)
A10: CAREER / STATUS
A11: profession | B11: Primary job title(s) — Footballer, Actor, Politician, Scientist, etc. | C11: All categories
A12: active | B12: Still working/competing | C12: All real-person categories
A13: retired | B13: No longer active in their career | C13: Most real-person categories
A14: popularity | B14: 1-100 fame tier, used for Easy/Medium/Hard/Expert difficulty filtering. A subjective ranking judgment, not a factual claim. | C14: All characters
A15: SPORT
A16: sport | B16: Sport played (Football, Cricket, Basketball, Motorsport) | C16: Footballers, Cricketers, F1, Basketball, some Indian Celebrities
A17: team | B17: Current or most-associated club/team | C17: Footballers, Cricketers, F1, Basketball
A18: league | B18: Competition/league | C18: Footballers, Cricketers, F1, Basketball
A19: position | B19: Playing position (Forward, Guard, Goalkeeper, etc.) | C19: Footballers, Basketball
A20: athlete | B20: Is a professional athlete | C20: Sport categories + some Famous Personalities/Indian Celebrities
A21: captain | B21: Has captained their team/country | C21: Cricketers, Footballers, Indian Celebrities
A22: batsman / bowler / allRounder / wicketKeeper | B22: Cricket playing role | C22: Cricketers, some Indian Celebrities
A23: worldCupWinner | B23: Won a World Cup (football or cricket) | C23: Footballers, Cricketers, Indian Celebrities
A24: championsLeagueWinner | B24: Won a Champions League title | C24: Footballers
A25: olympicMedalist | B25: Won an Olympic medal | C25: Basketball, Indian Celebrities, Famous Personalities
A26: champion | B26: Won the top individual title in their sport (F1 Drivers' title, NBA/WNBA championship, etc.) — generic across sports rather than one field per sport | C26: F1 Drivers, Basketball, Indian Celebrities
A27: ENTERTAINMENT
A28: actor / actress | B28: Works primarily as an actor/actress | C28: Actors, Actresses, Indian Celebrities, some Famous Personalities
A29: singer | B29: Works primarily as a singer | C29: Singers, Indian Celebrities
A30: director | B30: Has directed films | C30: Actors, Actresses, Indian Celebrities, Famous Personalities
A31: comedy | B31: Primarily known for comedy | C31: Actors, Actresses, Fictional, Gamers, Indian Celebrities
A32: marvel | B32: Has appeared in the Marvel universe | C32: Actors, Actresses, Fictional
A33: oscarWinner | B33: Won a competitive Academy Award | C33: Actors, Actresses, Indian Celebrities
A34: grammyWinner | B34: Won a competitive Grammy (or Latin Grammy) | C34: Singers, Indian Celebrities
A35: soloArtist / bandMember | B35: Performs solo vs. as part of a group | C35: Singers
A36: BUSINESS
A37: entrepreneur | B37: Founded or leads a company | C37: Tech & Business, Famous Personalities, Indian Celebrities, some others
A38: founder | B38: Personally founded their company | C38: Tech & Business, Indian Celebrities
A39: billionaire | B39: Estimated net worth over $1B | C39: Tech & Business, Famous Personalities, Indian Celebrities
A40: streamer | B40: Works as a streamer/YouTuber | C40: Gamers & Streamers
A41: FICTIONAL-ONLY
...

Sheet Distribution
A1: Guess Who — Character Distribution
A2: All counts below are live formulas reading the Characters sheet (4624 characters, rows 2-4625).
A4: By Category
A5: Category | B5: Characters | C5: % of Total
A6: Footballers | B6: =COUNTIF(Characters!$C$2:$C$4625,A6) | C6: =B6/4624
A7: Cricketers | B7: =COUNTIF(Characters!$C$2:$C$4625,A7) | C7: =B7/4624
A8: Actors | B8: =COUNTIF(Characters!$C$2:$C$4625,A8) | C8: =B8/4624
A9: Actresses | B9: =COUNTIF(Characters!$C$2:$C$4625,A9) | C9: =B9/4624
A10: Singers | B10: =COUNTIF(Characters!$C$2:$C$4625,A10) | C10: =B10/4624
A11: Famous Personalities | B11: =COUNTIF(Characters!$C$2:$C$4625,A11) | C11: =B11/4624
A12: F1 Drivers | B12: =COUNTIF(Characters!$C$2:$C$4625,A12) | C12: =B12/4624
A13: Basketball Players | B13: =COUNTIF(Characters!$C$2:$C$4625,A13) | C13: =B13/4624
A14: Gamers & Streamers | B14: =COUNTIF(Characters!$C$2:$C$4625,A14) | C14: =B14/4624
A15: Tech & Business | B15: =COUNTIF(Characters!$C$2:$C$4625,A15) | C15: =B15/4624
A16: Fictional Characters | B16: =COUNTIF(Characters!$C$2:$C$4625,A16) | C16: =B16/4624
A17: Indian Celebrities | B17: =COUNTIF(Characters!$C$2:$C$4625,A17) | C17: =B17/4624
A18: Total | B18: =SUM(B6:B17) | C18: =B18/4624
A21: By Gender
A22: Gender | B22: Characters | C22: % of Total
A23: Male | B23: =COUNTIF(Characters!$E$2:$E$4625,"male") | C23: =B23/4624
A24: Female | B24: =COUNTIF(Characters!$E$2:$E$4625,"female") | C24: =B24/4624
A25: Unspecified (fictional, historical) | B25: =4624-SUM(B23:B24) | C25: =B25/4624
A28: Active vs. Retired (where tracked)
A29: Status | B29: Characters
A30: Active | B30: =COUNTIF(Characters!$I$2:$I$4625,TRUE())
A31: Retired | B31: =COUNTIF(Characters!$J$2:$J$4625,TRUE())
A34: By Popularity Tier (difficulty filtering)
A35: Tier | B35: Characters | C35: Popularity Range
A36: Easy-eligible | B36: =COUNTIFS(Characters!$H$2:$H$4625,">="&75,Characters!$H$2:$H$4625,"<="&100) | C36: 75-100
A37: Medium-eligible | B37: =COUNTIFS(Characters!$H$2:$H$4625,">="&55,Characters!$H$2:$H$4625,"<="&74) | C37: 55-74
A38: Hard-eligible | B38: =COUNTIFS(Characters!$H$2:$H$4625,">="&35,Characters!$H$2:$H$4625,"<="&54) | C38: 35-54
A39: Expert-only (deep cuts) | B39: =COUNTIFS(Characters!$H$2:$H$4625,">="&0,Characters!$H$2:$H$4625,"<="&34) | C39: 0-34
A42: By Decade of Birth (real people only)
A43: Decade | B43: Characters
A44: 1860s | B44: =COUNTIFS(Characters!$G$2:$G$4625,">="&1860,Characters!$G$2:$G$4625,"<="&1869)
A45: 1870s | B45: =COUNTIFS(Characters!$G$2:$G$4625,">="&1870,Characters!$G$2:$G$4625,"<="&1879)
A46: 1880s | B46: =COUNTIFS(Characters!$G$2:$G$4625,">="&1880,Characters!$G$2:$G$4625,"<="&1889)
A47: 1890s | B47: =COUNTIFS(Characters!$G$2:$G$4625,">="&1890,Characters!$G$2:$G$4625,"<="&1899)
A48: 1900s | B48: =COUNTIFS(Characters!$G$2:$G$4625,">="&1900,Characters!$G$2:$G$4625,"<="&1909)
A49: 1910s | B49: =COUNTIFS(Characters!$G$2:$G$4625,">="&1910,Characters!$G$2:$G$4625,"<="&1919)
...
